<robot name="single_unitree_example">

    <link name="unitree" />

    <joint name="unitree_joint" type="continuous">
        <parent link="unitree" />
        <child link="none" />
    </joint>

    <transmission name="unitree_trans">
        <type>transmission_interface/SimpleTransmission</type>
        <joint name="unitree_joint">
            <hardwareInterface>hardware_interface/PosVelJointInterface</hardwareInterface>
            <hardwareInterface>hardware_interface_extensions/PosVelEffJointInterface</hardwareInterface>
            <hardwareInterface>hardware_interface/VelocityJointInterface</hardwareInterface>
            <hardwareInterface>hardware_interface/EffortJointInterface</hardwareInterface>
        </joint>
        <actuator name="unitree_actuator">
            <mechanicalReduction>1</mechanicalReduction>
        </actuator>
    </transmission>

    <link name="none" />

</robot>