<robot name="skid_steer_unitree_example">
    <link name="base_link"/>

    <link name="fr_wheel"/>
    <joint name="fr_wheel_joint" type="continuous">
        <parent link="base_link"/>
        <child link="fr_wheel"/>
    </joint>

    <transmission name="fr_trans">
        <type>transmission_interface/SimpleTransmission</type>
        <joint name="fr_joint">
            <hardwareInterface>hardware_interface/PosVelJointInterface</hardwareInterface>
            <hardwareInterface>hardware_interface/VelocityJointInterface</hardwareInterface>
            <hardwareInterface>hardware_interface/EffortJointInterface</hardwareInterface>
        </joint>
        <actuator name="fr_actuator">
            <mechanicalReduction>1</mechanicalReduction>
        </actuator>
    </transmission>  

    <link name="fl_wheel">
      <!-- <inertial>
        
      </inertial> -->
      <!-- <visual>
          <origin xyz="${xyz}" rpy="${rpy}" />
          <geometry>
              <cylinder radius="${radius}" length="${length}" />
          </geometry>
          <material name="${name}_material">
              <color rgba="${rgba}" />
          </material>
      </visual>
      <collision>
          <origin xyz="${xyz}" rpy="${rpy}" />
          <geometry>
              <cylinder radius="${radius}" length="${length}" />
          </geometry>
      </collision>       -->
    </link>
    <joint name="fl_wheel_joint" type="continuous">
        <parent link="base_link"/>
        <child link="fl_wheel"/>
    </joint>

    <transmission name="fl_trans">
        <type>transmission_interface/SimpleTransmission</type>
        <joint name="fl_joint">
            <hardwareInterface>hardware_interface/PosVelJointInterface</hardwareInterface>
            <hardwareInterface>hardware_interface/VelocityJointInterface</hardwareInterface>
            <hardwareInterface>hardware_interface/EffortJointInterface</hardwareInterface>
        </joint>
        <actuator name="fl_actuator">
            <mechanicalReduction>1</mechanicalReduction>
        </actuator>
    </transmission>  

    <link name="rr_wheel"/>
    <joint name="rr_wheel_joint" type="continuous">
        <parent link="base_link"/>
        <child link="rr_wheel"/>
    </joint>

    <transmission name="rr_trans">
        <type>transmission_interface/SimpleTransmission</type>
        <joint name="rr_joint">
            <hardwareInterface>hardware_interface/PosVelJointInterface</hardwareInterface>
            <hardwareInterface>hardware_interface/VelocityJointInterface</hardwareInterface>
            <hardwareInterface>hardware_interface/EffortJointInterface</hardwareInterface>
        </joint>
        <actuator name="rr_actuator">
            <mechanicalReduction>1</mechanicalReduction>
        </actuator>
    </transmission>  

    <link name="rl_wheel"/>
    <joint name="rl_wheel_joint" type="continuous">
        <parent link="base_link"/>
        <child link="rl_wheel"/>
    </joint>

    <transmission name="rl_trans">
        <type>transmission_interface/SimpleTransmission</type>
        <joint name="rl_joint">
            <hardwareInterface>hardware_interface/PosVelJointInterface</hardwareInterface>
            <hardwareInterface>hardware_interface/VelocityJointInterface</hardwareInterface>
            <hardwareInterface>hardware_interface/EffortJointInterface</hardwareInterface>
        </joint>
        <actuator name="rl_actuator">
            <mechanicalReduction>1</mechanicalReduction>
        </actuator>
    </transmission>  

</robot>